<sdf version='1.6'>
  <world name='default'>
    <light name='sun' type='directional'>
      <cast_shadows>1</cast_shadows>
      <pose frame=''>0 0 10 0 -0 0</pose>
      <diffuse>0.8 0.8 0.8 1</diffuse>
      <specular>0.2 0.2 0.2 1</specular>
      <attenuation>
        <range>1000</range>
        <constant>0.9</constant>
        <linear>0.01</linear>
        <quadratic>0.001</quadratic>
      </attenuation>
      <direction>-0.5 0.1 -0.9</direction>
    </light>
    <model name='ground_plane'>
      <static>1</static>
      <link name='link'>
        <collision name='collision'>
          <geometry>
            <plane>
              <normal>0 0 1</normal>
              <size>100 100</size>
            </plane>
          </geometry>
          <surface>
            <friction>
              <ode>
                <mu>100</mu>
                <mu2>50</mu2>
              </ode>
              <torsional>
                <ode/>
              </torsional>
            </friction>
            <contact>
              <ode/>
            </contact>
            <bounce/>
          </surface>
          <max_contacts>10</max_contacts>
        </collision>
        <visual name='visual'>
          <cast_shadows>0</cast_shadows>
          <geometry>
            <plane>
              <normal>0 0 1</normal>
              <size>100 100</size>
            </plane>
          </geometry>
          <material>
            <script>
              <uri>file://media/materials/scripts/gazebo.material</uri>
              <name>Gazebo/Grey</name>
            </script>
          </material>
        </visual>
        <self_collide>0</self_collide>
        <enable_wind>0</enable_wind>
        <kinematic>0</kinematic>
      </link>
    </model>
    <gravity>0 0 -9.8</gravity>
    <magnetic_field>6e-06 2.3e-05 -4.2e-05</magnetic_field>
    <atmosphere type='adiabatic'/>
    <physics name='default_physics' default='0' type='ode'>
      <max_step_size>0.001</max_step_size>
      <real_time_factor>1</real_time_factor>
      <real_time_update_rate>1000</real_time_update_rate>
    </physics>
    <scene>
      <ambient>0.4 0.4 0.4 1</ambient>
      <background>0.7 0.7 0.7 1</background>
      <shadows>1</shadows>
    </scene>
    <wind/>
    <spherical_coordinates>
      <surface_model>EARTH_WGS84</surface_model>
      <latitude_deg>0</latitude_deg>
      <longitude_deg>0</longitude_deg>
      <elevation>0</elevation>
      <heading_deg>0</heading_deg>
    </spherical_coordinates>
    <model name='Bobby'>
      <link name='body'>
        <pose frame=''>0 0 0.125 0 -0 0</pose>
        <gravity>1</gravity>
        <velocity_decay>
          <linear>0</linear>
          <angular>0</angular>
        </velocity_decay>
        <self_collide>1</self_collide>
        <inertial>
          <pose frame=''>-0.7227 0 0.2 0 -0 0</pose>
          <mass>2500</mass>
          <inertia>
            <ixx>800</ixx>
            <ixy>0</ixy>
            <ixz>0</ixz>
            <iyy>1200</iyy>
            <iyz>0</iyz>
            <izz>1000</izz>
          </inertia>
        </inertial>
        <visual name='body_visual'>
          <pose frame=''>0 0 0 0 -0 0</pose>
          <geometry>
            <mesh>
              <scale>1 1 1</scale>
              <uri>model://bobcat/meshes/body.dae</uri>
            </mesh>
          </geometry>
        </visual>
        <collision name='body_collision'>
          <pose frame=''>-0.82136 0 0.36982 0 -0.02 0</pose>
          <geometry>
            <box>
              <size>1.704 0.889 0.704</size>
            </box>
          </geometry>
          <max_contacts>10</max_contacts>
          <surface>
            <contact>
              <ode/>
            </contact>
            <bounce/>
            <friction>
              <torsional>
                <ode/>
              </torsional>
              <ode/>
            </friction>
          </surface>
        </collision>
        <collision name='body_collision_bb'>
          <pose frame=''>-2.14939 0 0.68567 0 0.08047 0</pose>
          <geometry>
            <box>
              <size>0.12 0.952 0.9</size>
            </box>
          </geometry>
          <max_contacts>10</max_contacts>
          <surface>
            <contact>
              <ode/>
            </contact>
            <bounce/>
            <friction>
              <torsional>
                <ode/>
              </torsional>
              <ode/>
            </friction>
          </surface>
        </collision>
        <collision name='body_collision_b'>
          <pose frame=''>-1.87754 0 0.671 0 0.08047 0</pose>
          <geometry>
            <box>
              <size>0.4 1.182 1.121</size>
            </box>
          </geometry>
          <max_contacts>10</max_contacts>
          <surface>
            <contact>
              <ode/>
            </contact>
            <bounce/>
            <friction>
              <torsional>
                <ode/>
              </torsional>
              <ode/>
            </friction>
          </surface>
        </collision>
        <collision name='body_collision_bd'>
          <pose frame=''>-1.81524 0 0.37981 0 0.1318 0</pose>
          <geometry>
            <box>
              <size>0.511 0.889 0.704</size>
            </box>
          </geometry>
          <max_contacts>10</max_contacts>
          <surface>
            <contact>
              <ode/>
            </contact>
            <bounce/>
            <friction>
              <torsional>
                <ode/>
              </torsional>
              <ode/>
            </friction>
          </surface>
        </collision>
        <collision name='body_collision_cabin'>
          <pose frame=''>-1.0253 0 1.24 0 -0 0</pose>
          <geometry>
            <box>
              <size>1.557 0.889 1.152</size>
            </box>
          </geometry>
          <max_contacts>10</max_contacts>
          <surface>
            <contact>
              <ode/>
            </contact>
            <bounce/>
            <friction>
              <torsional>
                <ode/>
              </torsional>
              <ode/>
            </friction>
          </surface>
        </collision>
        <collision name='body_collision_top_installation_link'>
          <pose frame=''>-0.92913 0 2.04 0 -0 0</pose>
          <geometry>
            <box>
              <size>0.663 0.598 0.838</size>
            </box>
          </geometry>
          <max_contacts>10</max_contacts>
          <surface>
            <contact>
              <ode/>
            </contact>
            <bounce/>
            <friction>
              <torsional>
                <ode/>
              </torsional>
              <ode/>
            </friction>
          </surface>
        </collision>
        <enable_wind>0</enable_wind>
        <kinematic>0</kinematic>
      </link>
      <link name='base_arm'>
        <pose frame=''>-1.9776 0 1.1773 0 -0 0</pose>
        <inertial>
          <pose frame=''>0.066509 0 0.25686 0 -0 0</pose>
          <mass>400</mass>
          <inertia>
            <ixx>50.76</ixx>
            <ixy>0</ixy>
            <ixz>0.66798</ixz>
            <iyy>4.8017</iyy>
            <iyz>0</iyz>
            <izz>47.388</izz>
          </inertia>
        </inertial>
        <collision name='base_arm_collision'>
          <pose frame=''>0 0 0 0 -0 0</pose>
          <geometry>
            <mesh>
              <scale>1 1 1</scale>
              <uri>model://bobcat/meshes/base_arm_col.stl</uri>
            </mesh>
          </geometry>
          <surface>
            <contact>
              <ode/>
            </contact>
            <friction>
              <ode/>
              <torsional>
                <ode/>
              </torsional>
            </friction>
            <bounce/>
          </surface>
          <max_contacts>10</max_contacts>
        </collision>
        <visual name='base_arm_visual'>
          <pose frame=''>0 0 0 0 -0 0</pose>
          <geometry>
            <mesh>
              <scale>1 1 1</scale>
              <uri>model://bobcat/meshes/base_arm.stl</uri>
            </mesh>
          </geometry>
          <material>
            <script>
              <name>Gazebo/Grey</name>
              <uri>__default__</uri>
            </script>
          </material>
        </visual>
        <gravity>1</gravity>
        <velocity_decay>
          <linear>0</linear>
          <angular>0</angular>
        </velocity_decay>
        <self_collide>0</self_collide>
        <enable_wind>0</enable_wind>
        <kinematic>0</kinematic>
      </link>
      <joint name='base_arm_joint' type='revolute'>
        <child>base_arm</child>
        <parent>body</parent>
        <axis>
          <xyz>0 1 0</xyz>
          <use_parent_model_frame>1</use_parent_model_frame>
          <limit>
            <lower>-1e+16</lower>
            <upper>1e+16</upper>
          </limit>
          <dynamics>
            <spring_reference>0</spring_reference>
            <spring_stiffness>0</spring_stiffness>
          </dynamics>
        </axis>
      </joint>
      <link name='main_arm'>
        <pose frame=''>-1.75456 0 1.7035 0 -0 0</pose>
        <inertial>
          <pose frame=''>1.1865 0 -0.60466 0 -0 0</pose>
          <mass>300</mass>
          <inertia>
            <ixx>133.74</ixx>
            <ixy>0</ixy>
            <ixz>0</ixz>
            <iyy>216.24</iyy>
            <iyz>0</iyz>
            <izz>268.55</izz>
          </inertia>
        </inertial>
        <collision name='main_arm_collision'>
          <pose frame=''>0 0 0 0 -0 0</pose>
          <geometry>
            <mesh>
              <scale>1 1 1</scale>
              <uri>model://bobcat/meshes/main_arm_col.stl</uri>
            </mesh>
          </geometry>
          <surface>
            <contact>
              <ode/>
            </contact>
            <friction>
              <ode/>
              <torsional>
                <ode/>
              </torsional>
            </friction>
            <bounce/>
          </surface>
          <max_contacts>10</max_contacts>
        </collision>
        <visual name='main_arm_visual'>
          <pose frame=''>0 0 0 0 -0 0</pose>
          <geometry>
            <mesh>
              <scale>1 1 1</scale>
              <uri>model://bobcat/meshes/main_arm.stl</uri>
            </mesh>
          </geometry>
          <material>
            <diffuse>0.9 0.9 0.89 1</diffuse>
            <ambient>0.85 0.85 0.78 1</ambient>
          </material>
        </visual>
        <gravity>1</gravity>
        <velocity_decay>
          <linear>0</linear>
          <angular>0</angular>
        </velocity_decay>
        <self_collide>0</self_collide>
        <enable_wind>0</enable_wind>
        <kinematic>0</kinematic>
      </link>
      <joint name='main_arm_joint' type='revolute'>
        <child>main_arm</child>
        <parent>base_arm</parent>
        <axis>
          <xyz>0 1 0</xyz>
          <use_parent_model_frame>1</use_parent_model_frame>
          <limit>
            <lower>-1e+16</lower>
            <upper>1e+16</upper>
          </limit>
          <dynamics>
            <spring_reference>0</spring_reference>
            <spring_stiffness>0</spring_stiffness>
          </dynamics>
        </axis>
      </joint>
      <link name='loader'>
        <pose frame=''>0.34384 0 0.1465 0 -0 0</pose>
        <inertial>
          <pose frame=''>0.37894 0 0.067409 0 -0 0</pose>
          <mass>98.03</mass>
          <inertia>
            <ixx>29.346</ixx>
            <ixy>0</ixy>
            <ixz>0</ixz>
            <iyy>9.25</iyy>
            <iyz>0</iyz>
            <izz>32.05</izz>
          </inertia>
        </inertial>
        <collision name='loader_collision'>
          <pose frame=''>0.54 0 -0.09 0 -0 0</pose>
          <geometry>
            <mesh>
              <scale>0.1 0.1 0.1</scale>
              <uri>model://bobcat/meshes/loader_col.stl</uri>
            </mesh>
          </geometry>
          <surface>
            <contact>
              <ode/>
            </contact>
            <friction>
              <ode>
                <mu>1</mu>
                <mu2>1</mu2>
              </ode>
              <torsional>
                <ode/>
              </torsional>
            </friction>
            <bounce/>
          </surface>
          <max_contacts>10</max_contacts>
        </collision>
        <visual name='loader_visual'>
          <pose frame=''>0 0 0 0 -0 0</pose>
          <geometry>
            <mesh>
              <scale>1 1 1</scale>
              <uri>model://bobcat/meshes/loader.stl</uri>
            </mesh>
          </geometry>
          <material>
            <diffuse>0.2 0.2 0.2 1</diffuse>
            <ambient>0.2 0.2 0.2 1</ambient>
          </material>
        </visual>
        <gravity>1</gravity>
        <velocity_decay>
          <linear>0</linear>
          <angular>0</angular>
        </velocity_decay>
        <self_collide>1</self_collide>
        <enable_wind>0</enable_wind>
        <kinematic>0</kinematic>
      </link>
      <joint name='loader_joint' type='revolute'>
        <child>loader</child>
        <parent>main_arm</parent>
        <axis>
          <xyz>0 -1 0</xyz>
          <limit>
            <lower>-0.9</lower>
            <upper>0.5</upper>
            <effort>1e+06</effort>
            <velocity>100</velocity>
          </limit>
          <dynamics>
            <damping>0.5</damping>
            <friction>2500</friction>
            <spring_reference>0</spring_reference>
            <spring_stiffness>0</spring_stiffness>
          </dynamics>
          <use_parent_model_frame>1</use_parent_model_frame>
        </axis>
      </joint>
      <link name='brackets'>
        <pose frame=''>0.68217 0 0.64099 0 -0 0</pose>
        <inertial>
          <pose frame=''>0.14213 0 0.33109 0 -0 0</pose>
          <mass>12.857</mass>
          <inertia>
            <ixx>2.9339</ixx>
            <ixy>0</ixy>
            <ixz>0.23718</ixz>
            <iyy>0.67251</iyy>
            <iyz>0</iyz>
            <izz>2.738</izz>
          </inertia>
        </inertial>
        <collision name='brackets_collision'>
          <pose frame=''>0 0 0 0 -0 0</pose>
          <geometry>
            <mesh>
              <scale>1 1 1</scale>
              <uri>model://bobcat/meshes/brackets_col.stl</uri>
            </mesh>
          </geometry>
          <surface>
            <contact>
              <ode/>
            </contact>
            <friction>
              <ode>
                <mu>1</mu>
                <mu2>1</mu2>
              </ode>
              <torsional>
                <ode/>
              </torsional>
            </friction>
            <bounce/>
          </surface>
          <max_contacts>10</max_contacts>
        </collision>
        <visual name='brackets_visual'>
          <pose frame=''>0 0 0 0 -0 0</pose>
          <geometry>
            <mesh>
              <scale>1 1 1</scale>
              <uri>model://bobcat/meshes/brackets.stl</uri>
            </mesh>
          </geometry>
          <material>
            <diffuse>0.1 0.1 0.1 1</diffuse>
            <ambient>0.1 0.1 0.1 1</ambient>
          </material>
        </visual>
        <gravity>1</gravity>
        <velocity_decay>
          <linear>0</linear>
          <angular>0</angular>
        </velocity_decay>
        <self_collide>1</self_collide>
        <enable_wind>0</enable_wind>
        <kinematic>0</kinematic>
      </link>
      <joint name='brackets_joint' type='revolute'>
        <child>brackets</child>
        <parent>loader</parent>
        <axis>
          <xyz>0 1 0</xyz>
          <limit>
            <lower>-0.5</lower>
            <upper>1</upper>
            <effort>1e+06</effort>
            <velocity>1e+06</velocity>
          </limit>
          <dynamics>
            <damping>0.5</damping>
            <friction>200</friction>
            <spring_reference>0</spring_reference>
            <spring_stiffness>0</spring_stiffness>
          </dynamics>
          <use_parent_model_frame>1</use_parent_model_frame>
        </axis>
      </joint>
      <link name='supporter'>
        <pose frame=''>-1.35685 0 0.80864 0 -0.12 0</pose>
        <inertial>
          <pose frame=''>0.51341 0 -0.060486 0 -0 0</pose>
          <mass>30</mass>
          <inertia>
            <ixx>16.898</ixx>
            <ixy>0</ixy>
            <ixz>0</ixz>
            <iyy>6.6127</iyy>
            <iyz>0</iyz>
            <izz>23.301</izz>
          </inertia>
        </inertial>
        <collision name='supporter_collision'>
          <pose frame=''>0 0 0 0 -0 0</pose>
          <geometry>
            <mesh>
              <scale>1 1 1</scale>
              <uri>model://bobcat/meshes/supporter.stl</uri>
            </mesh>
          </geometry>
          <surface>
            <contact>
              <ode/>
            </contact>
            <friction>
              <ode>
                <mu>1</mu>
                <mu2>1</mu2>
              </ode>
              <torsional>
                <ode/>
              </torsional>
            </friction>
            <bounce/>
          </surface>
          <max_contacts>10</max_contacts>
        </collision>
        <visual name='supporter_visual'>
          <pose frame=''>0 0 0 0 -0 0</pose>
          <geometry>
            <mesh>
              <scale>1 1 1</scale>
              <uri>model://bobcat/meshes/supporter.stl</uri>
            </mesh>
          </geometry>
          <material>
            <diffuse>0.8 0.1 0.1 1</diffuse>
            <ambient>0.8 0.1 0.1 1</ambient>
          </material>
        </visual>
        <gravity>1</gravity>
        <velocity_decay>
          <linear>0</linear>
          <angular>0</angular>
        </velocity_decay>
        <self_collide>1</self_collide>
        <enable_wind>0</enable_wind>
        <kinematic>0</kinematic>
      </link>
      <joint name='supporter_joint' type='revolute'>
        <child>supporter</child>
        <parent>main_arm</parent>
        <axis>
          <xyz>0 1 0</xyz>
          <use_parent_model_frame>1</use_parent_model_frame>
          <limit>
            <lower>-1e+16</lower>
            <upper>1e+16</upper>
          </limit>
          <dynamics>
            <spring_reference>0</spring_reference>
            <spring_stiffness>0</spring_stiffness>
          </dynamics>
        </axis>
      </joint>
      <joint name='supporter_joint2' type='revolute'>
        <pose frame=''>1.04 0 -0.122 0 -0 0</pose>
        <child>supporter</child>
        <parent>body</parent>
        <axis>
          <xyz>0 1 0</xyz>
          <use_parent_model_frame>1</use_parent_model_frame>
          <limit>
            <lower>-1e+16</lower>
            <upper>1e+16</upper>
          </limit>
          <dynamics>
            <spring_reference>0</spring_reference>
            <spring_stiffness>0</spring_stiffness>
          </dynamics>
        </axis>
      </joint>
      <link name='Hydraulics_bottom'>
        <pose frame=''>-1.781 0 0.393 0 0.34907 0</pose>
        <inertial>
          <pose frame=''>0 0 0.5 0 -0 0</pose>
          <mass>65.29</mass>
          <inertia>
            <ixx>10</ixx>
            <ixy>0</ixy>
            <ixz>0</ixz>
            <iyy>10</iyy>
            <iyz>0</iyz>
            <izz>1</izz>
          </inertia>
        </inertial>
        <self_collide>0</self_collide>
        <visual name='Hydraulics_bottom_vis'>
          <pose frame=''>0 0 0 0 -0 0</pose>
          <geometry>
            <mesh>
              <scale>1 1 1</scale>
              <uri>model://bobcat/meshes/Hydraulics_bottom.dae</uri>
            </mesh>
          </geometry>
        </visual>
        <enable_wind>0</enable_wind>
        <kinematic>0</kinematic>
      </link>
      <joint name='Hydraulics_bottom_rot' type='revolute'>
        <pose frame=''>0 0 0 0 -0 0</pose>
        <child>Hydraulics_bottom</child>
        <parent>body</parent>
        <axis>
          <xyz>0 1 0</xyz>
          <use_parent_model_frame>1</use_parent_model_frame>
          <limit>
            <lower>-1e+16</lower>
            <upper>1e+16</upper>
          </limit>
          <dynamics>
            <spring_reference>0</spring_reference>
            <spring_stiffness>0</spring_stiffness>
          </dynamics>
        </axis>
      </joint>
      <link name='Hydraulics_top'>
        <pose frame=''>-1.48 0 1.22 0 0.34907 0</pose>
        <inertial>
          <pose frame=''>0 0 -0.5 0 -0 0</pose>
          <mass>65.29</mass>
          <inertia>
            <ixx>10</ixx>
            <ixy>0</ixy>
            <ixz>0</ixz>
            <iyy>10</iyy>
            <iyz>0</iyz>
            <izz>1</izz>
          </inertia>
        </inertial>
        <self_collide>0</self_collide>
        <visual name='Hydraulics_bottom_vis'>
          <pose frame=''>0 0 0 0 -0 0</pose>
          <geometry>
            <mesh>
              <scale>1 1 1</scale>
              <uri>model://bobcat/meshes/Hydraulics_top.dae</uri>
            </mesh>
          </geometry>
        </visual>
        <enable_wind>0</enable_wind>
        <kinematic>0</kinematic>
      </link>
      <joint name='Hydraulics_top_rot' type='revolute'>
        <pose frame=''>0 0 0 0 -0 0</pose>
        <child>Hydraulics_top</child>
        <parent>main_arm</parent>
        <axis>
          <xyz>0 1 0</xyz>
          <use_parent_model_frame>1</use_parent_model_frame>
          <limit>
            <lower>-1e+16</lower>
            <upper>1e+16</upper>
          </limit>
          <dynamics>
            <spring_reference>0</spring_reference>
            <spring_stiffness>0</spring_stiffness>
          </dynamics>
        </axis>
      </joint>
      <joint name='Hydraulics_joint' type='prismatic'>
        <pose frame=''>0 0 -0.5 0 -0 0</pose>
        <child>Hydraulics_top</child>
        <parent>Hydraulics_bottom</parent>
        <axis>
          <limit>
            <lower>-0.1</lower>
            <upper>0.38</upper>
          </limit>
          <xyz>0.342024 0 0.939691</xyz>
          <dynamics>
            <damping>0.5</damping>
            <friction>100</friction>
            <spring_reference>0</spring_reference>
            <spring_stiffness>0</spring_stiffness>
          </dynamics>
          <use_parent_model_frame>1</use_parent_model_frame>
        </axis>
      </joint>
      <link name='back_left_wheel'>
        <pose frame=''>-1.227 0.47558 0.3 0 -0 0</pose>
        <inertial>
          <pose frame=''>0 0.19645 0 0 -0 0</pose>
          <mass>333.358</mass>
          <inertia>
            <ixx>17.0765</ixx>
            <ixy>0</ixy>
            <ixz>0</ixz>
            <iyy>29.6158</iyy>
            <iyz>0</iyz>
            <izz>17.0765</izz>
          </inertia>
        </inertial>
        <collision name='back_left_wheel_collision'>
          <pose frame=''>0 0.2 0 1.5708 -0 0</pose>
          <geometry>
            <cylinder>
              <length>0.4</length>
              <radius>0.4</radius>
            </cylinder>
          </geometry>
          <surface>
            <contact>
              <ode/>
            </contact>
            <friction>
              <ode>
                <mu>1</mu>
                <mu2>1</mu2>
              </ode>
              <torsional>
                <ode/>
              </torsional>
            </friction>
            <bounce/>
          </surface>
          <max_contacts>10</max_contacts>
        </collision>
        <visual name='back_left_wheel_visual'>
          <pose frame=''>0 0 0 0 -0 0</pose>
          <geometry>
            <mesh>
              <uri>model://bobcat/meshes/back_left_wheel.stl</uri>
            </mesh>
          </geometry>
          <material>
            <ambient>0 0 0 1</ambient>
            <diffuse>0.1 0.1 0.1 1</diffuse>
            <specular>0.5 0.5 0.5 1</specular>
            <emissive>0.05 0.05 0.05 1</emissive>
          </material>
        </visual>
        <gravity>1</gravity>
        <velocity_decay>
          <linear>0</linear>
          <angular>0</angular>
        </velocity_decay>
        <self_collide>0</self_collide>
        <enable_wind>0</enable_wind>
        <kinematic>0</kinematic>
      </link>
      <joint name='back_left_wheel_joint' type='revolute'>
        <child>back_left_wheel</child>
        <parent>body</parent>
        <axis>
          <xyz>0 1 0</xyz>
          <dynamics>
            <damping>0.999</damping>
            <friction>50</friction>
            <spring_reference>0</spring_reference>
            <spring_stiffness>0</spring_stiffness>
          </dynamics>
          <use_parent_model_frame>1</use_parent_model_frame>
          <limit>
            <lower>-1e+16</lower>
            <upper>1e+16</upper>
          </limit>
        </axis>
      </joint>
      <link name='back_right_wheel'>
        <pose frame=''>-1.227 -0.47558 0.3 0 -0 0</pose>
        <inertial>
          <pose frame=''>-0 -0.19645 0 0 -0 0</pose>
          <mass>333.36</mass>
          <inertia>
            <ixx>17.0765</ixx>
            <ixy>0</ixy>
            <ixz>0</ixz>
            <iyy>29.6158</iyy>
            <iyz>0</iyz>
            <izz>17.0765</izz>
          </inertia>
        </inertial>
        <collision name='back_right_wheel_collision'>
          <pose frame=''>0 -0.2 0 1.5708 -0 0</pose>
          <geometry>
            <cylinder>
              <length>0.4</length>
              <radius>0.4</radius>
            </cylinder>
          </geometry>
          <surface>
            <contact>
              <ode/>
            </contact>
            <friction>
              <ode>
                <mu>1</mu>
                <mu2>1</mu2>
              </ode>
              <torsional>
                <ode/>
              </torsional>
            </friction>
            <bounce/>
          </surface>
          <max_contacts>10</max_contacts>
        </collision>
        <visual name='back_right_wheel_visual'>
          <pose frame=''>0 0 0 0 -0 0</pose>
          <geometry>
            <mesh>
              <scale>1 1 1</scale>
              <uri>model://bobcat/meshes/back_right_wheel.stl</uri>
            </mesh>
          </geometry>
          <material>
            <ambient>0 0 0 1</ambient>
            <diffuse>0.1 0.1 0.1 1</diffuse>
            <specular>0.5 0.5 0.5 1</specular>
            <emissive>0.05 0.05 0.05 1</emissive>
          </material>
        </visual>
        <gravity>1</gravity>
        <velocity_decay>
          <linear>0</linear>
          <angular>0</angular>
        </velocity_decay>
        <self_collide>1</self_collide>
        <enable_wind>0</enable_wind>
        <kinematic>0</kinematic>
      </link>
      <joint name='back_right_wheel_joint' type='revolute'>
        <child>back_right_wheel</child>
        <parent>body</parent>
        <axis>
          <xyz>0 1 0</xyz>
          <dynamics>
            <damping>0.999</damping>
            <friction>50</friction>
            <spring_reference>0</spring_reference>
            <spring_stiffness>0</spring_stiffness>
          </dynamics>
          <use_parent_model_frame>1</use_parent_model_frame>
          <limit>
            <lower>-1e+16</lower>
            <upper>1e+16</upper>
          </limit>
        </axis>
      </joint>
      <link name='front_left_wheel'>
        <pose frame=''>-0.22722 0.47558 0.3 0 -0 0</pose>
        <inertial>
          <pose frame=''>0 0.19645 -0 0 -0 0</pose>
          <mass>333.358</mass>
          <inertia>
            <ixx>17.0765</ixx>
            <ixy>0</ixy>
            <ixz>0</ixz>
            <iyy>29.6158</iyy>
            <iyz>0</iyz>
            <izz>17.0765</izz>
          </inertia>
        </inertial>
        <collision name='front_left_wheel_collision'>
          <pose frame=''>0 0.2 0 1.5708 -0 0</pose>
          <geometry>
            <cylinder>
              <length>0.4</length>
              <radius>0.4</radius>
            </cylinder>
          </geometry>
          <surface>
            <contact>
              <ode/>
            </contact>
            <friction>
              <ode>
                <mu>1</mu>
                <mu2>1</mu2>
              </ode>
              <torsional>
                <ode/>
              </torsional>
            </friction>
            <bounce/>
          </surface>
          <max_contacts>10</max_contacts>
        </collision>
        <visual name='front_left_wheel_visual'>
          <pose frame=''>0 0 0 0 -0 0</pose>
          <geometry>
            <mesh>
              <scale>1 1 1</scale>
              <uri>model://bobcat/meshes/front_left_wheel.stl</uri>
            </mesh>
          </geometry>
          <material>
            <ambient>0 0 0 1</ambient>
            <diffuse>0.1 0.1 0.1 1</diffuse>
            <specular>0.5 0.5 0.5 1</specular>
            <emissive>0.05 0.05 0.05 1</emissive>
          </material>
        </visual>
        <gravity>1</gravity>
        <velocity_decay>
          <linear>0</linear>
          <angular>0</angular>
        </velocity_decay>
        <self_collide>1</self_collide>
        <enable_wind>0</enable_wind>
        <kinematic>0</kinematic>
      </link>
      <joint name='front_left_wheel_joint' type='revolute'>
        <child>front_left_wheel</child>
        <parent>body</parent>
        <axis>
          <xyz>0 1 0</xyz>
          <dynamics>
            <damping>0.999</damping>
            <friction>50</friction>
            <spring_reference>0</spring_reference>
            <spring_stiffness>0</spring_stiffness>
          </dynamics>
          <use_parent_model_frame>1</use_parent_model_frame>
          <limit>
            <lower>-1e+16</lower>
            <upper>1e+16</upper>
          </limit>
        </axis>
      </joint>
      <link name='front_right_wheel'>
        <pose frame=''>-0.22722 -0.47558 0.3 0 -0 0</pose>
        <inertial>
          <pose frame=''>-0 -0.19645 -0 0 -0 0</pose>
          <mass>333.358</mass>
          <inertia>
            <ixx>17.0765</ixx>
            <ixy>0</ixy>
            <ixz>0</ixz>
            <iyy>29.6158</iyy>
            <iyz>0</iyz>
            <izz>17.0765</izz>
          </inertia>
        </inertial>
        <collision name='front_right_wheel_collision'>
          <pose frame=''>0 -0.2 0 1.5708 -0 0</pose>
          <geometry>
            <cylinder>
              <length>0.4</length>
              <radius>0.4</radius>
            </cylinder>
          </geometry>
          <surface>
            <contact>
              <ode/>
            </contact>
            <friction>
              <ode>
                <mu>1</mu>
                <mu2>1</mu2>
              </ode>
              <torsional>
                <ode/>
              </torsional>
            </friction>
            <bounce/>
          </surface>
          <max_contacts>10</max_contacts>
        </collision>
        <visual name='front_right_wheel_visual'>
          <pose frame=''>0 0 0 0 -0 0</pose>
          <geometry>
            <mesh>
              <scale>1 1 1</scale>
              <uri>model://bobcat/meshes/front_right_wheel.stl</uri>
            </mesh>
          </geometry>
          <material>
            <ambient>0 0 0 1</ambient>
            <diffuse>0.1 0.1 0.1 1</diffuse>
            <specular>0.5 0.5 0.5 1</specular>
            <emissive>0.05 0.05 0.05 1</emissive>
          </material>
        </visual>
        <gravity>1</gravity>
        <velocity_decay>
          <linear>0</linear>
          <angular>0</angular>
        </velocity_decay>
        <self_collide>1</self_collide>
        <enable_wind>0</enable_wind>
        <kinematic>0</kinematic>
      </link>
      <joint name='front_right_wheel_joint' type='revolute'>
        <child>front_right_wheel</child>
        <parent>body</parent>
        <axis>
          <xyz>0 1 0</xyz>
          <dynamics>
            <damping>0.999</damping>
            <friction>50</friction>
            <spring_reference>0</spring_reference>
            <spring_stiffness>0</spring_stiffness>
          </dynamics>
          <use_parent_model_frame>1</use_parent_model_frame>
          <limit>
            <lower>-1e+16</lower>
            <upper>1e+16</upper>
          </limit>
        </axis>
      </joint>
      <pose frame=''>-1.65695 0.037976 0 0 -0 0</pose>
    </model>
    <model name='sand_pile3'>
      <link name='link_0'>
        <pose frame=''>-1.58159 -3.39888 0 0 -0 0</pose>
        <inertial>
          <mass>1</mass>
          <inertia>
            <ixx>0.166667</ixx>
            <ixy>0</ixy>
            <ixz>0</ixz>
            <iyy>0.166667</iyy>
            <iyz>0</iyz>
            <izz>0.166667</izz>
          </inertia>
        </inertial>
        <visual name='visual'>
          <pose frame=''>0 0 0 0 -0 0</pose>
          <geometry>
            <mesh>
              <uri>model://sand_pile3/sand_pile3.stl</uri>
              <scale>2 2 2</scale>
            </mesh>
          </geometry>
          <material>
            <lighting>1</lighting>
            <script>
              <uri>file://media/materials/scripts/gazebo.material</uri>
              <name>Gazebo/Yellow</name>
            </script>
            <ambient>0.3 0.25 0.1 1</ambient>
            <diffuse>0.7 0.6 0.4 1</diffuse>
            <specular>0.01 0.005 0.001 1</specular>
            <emissive>0 0 0 1</emissive>
          </material>
          <transparency>0</transparency>
          <cast_shadows>1</cast_shadows>
        </visual>
        <self_collide>0</self_collide>
        <enable_wind>0</enable_wind>
        <kinematic>0</kinematic>
      </link>
      <static>1</static>
      <allow_auto_disable>1</allow_auto_disable>
      <pose frame=''>-0.972054 -4.51104 0 0 -0 0</pose>
    </model>
    <model name='sandy_plane'>
      <link name='link_8'>
        <pose frame=''>0 0 0 0 -0 0</pose>
        <inertial>
          <mass>1</mass>
          <inertia>
            <ixx>0.166667</ixx>
            <ixy>0</ixy>
            <ixz>0</ixz>
            <iyy>0.166667</iyy>
            <iyz>0</iyz>
            <izz>0.166667</izz>
          </inertia>
          <pose frame=''>64 0 0 0 -0 0</pose>
        </inertial>
        <self_collide>0</self_collide>
        <kinematic>0</kinematic>
        <gravity>1</gravity>
        <visual name='visual'>
          <pose frame=''>64 0 0 0 -0 0</pose>
          <geometry>
            <mesh>
              <uri>model://smooth_ground/meshes/squareSmooth.dae</uri>
              <scale>16 16 1</scale>
            </mesh>
          </geometry>
          <material>
            <script>
              <uri>model://smooth_ground/materials/scripts</uri>
              <uri>model://smooth_ground/materials/textures</uri>
              <name>Smooth_ground/Diffuse</name>
            </script>
            <shader type='pixel'>
              <normal_map>__default__</normal_map>
            </shader>
            <ambient>1 1 1 1</ambient>
            <diffuse>1 1 1 1</diffuse>
            <specular>0 0 0 1</specular>
            <emissive>0 0 0 1</emissive>
          </material>
          <transparency>0</transparency>
          <cast_shadows>1</cast_shadows>
        </visual>
        <collision name='collision'>
          <laser_retro>0</laser_retro>
          <max_contacts>10</max_contacts>
          <pose frame=''>64 0 0 0 -0 0</pose>
          <geometry>
            <mesh>
              <uri>/home/omri/.gazebo/models/smooth_ground/meshes/squareSmooth.dae</uri>
              <scale>16 16 1</scale>
            </mesh>
          </geometry>
          <surface>
            <friction>
              <ode>
                <mu>1</mu>
                <mu2>1</mu2>
                <fdir1>0 0 0</fdir1>
                <slip1>0</slip1>
                <slip2>0</slip2>
              </ode>
              <torsional>
                <coefficient>1</coefficient>
                <patch_radius>0</patch_radius>
                <surface_radius>0</surface_radius>
                <use_patch_radius>1</use_patch_radius>
                <ode>
                  <slip>0</slip>
                </ode>
              </torsional>
            </friction>
            <bounce>
              <restitution_coefficient>0</restitution_coefficient>
              <threshold>1e+06</threshold>
            </bounce>
            <contact>
              <collide_without_contact>0</collide_without_contact>
              <collide_without_contact_bitmask>1</collide_without_contact_bitmask>
              <collide_bitmask>1</collide_bitmask>
              <ode>
                <soft_cfm>0</soft_cfm>
                <soft_erp>0.2</soft_erp>
                <kp>1e+13</kp>
                <kd>1</kd>
                <max_vel>0.01</max_vel>
                <min_depth>0</min_depth>
              </ode>
              <bullet>
                <split_impulse>1</split_impulse>
                <split_impulse_penetration_threshold>-0.01</split_impulse_penetration_threshold>
                <soft_cfm>0</soft_cfm>
                <soft_erp>0.2</soft_erp>
                <kp>1e+13</kp>
                <kd>1</kd>
              </bullet>
            </contact>
          </surface>
        </collision>
        <enable_wind>0</enable_wind>
      </link>
      <static>1</static>
      <allow_auto_disable>1</allow_auto_disable>
      <pose frame=''>-1.07592 1.8091 0 0 -0 0</pose>
    </model>
    <state world_name='default'>
      <sim_time>161 782000000</sim_time>
      <real_time>166 496111902</real_time>
      <wall_time>1555928704 788281684</wall_time>
      <iterations>161782</iterations>
      <model name='Bobby'>
        <pose frame=''>-1.6803 0.050017 0.100003 -1e-06 -2e-06 -0.023837</pose>
        <scale>1 1 1</scale>
        <link name='Hydraulics_bottom'>
          <pose frame=''>-3.46079 0.092467 0.493 -1e-06 0.397904 -0.023838</pose>
          <velocity>-0.000189 0.000845 0.002344 0.001537 0.001525 -0.000722</velocity>
          <acceleration>1.80204 -2.76608 4.92244 0.394926 -1.09087 -2.78699</acceleration>
          <wrench>117.655 -180.598 321.386 0 -0 0</wrench>
        </link>
        <link name='Hydraulics_top'>
          <pose frame=''>-3.13228 0.084636 1.27479 -1e-06 0.397905 -0.023838</pose>
          <velocity>0.00099 -0.000586 0.00182 0.001505 0.001526 -0.000722</velocity>
          <acceleration>1.26677 -2.12141 5.37876 0.445567 -1.08907 -2.70091</acceleration>
          <wrench>82.7073 -138.507 351.179 0 -0 0</wrench>
        </link>
        <link name='back_left_wheel'>
          <pose frame=''>-2.89561 0.554706 0.400003 -1.2e-05 -0.115447 -0.023836</pose>
          <velocity>-3.1e-05 0.000189 0.002908 -0.00037 0.000614 -0.00069</velocity>
          <acceleration>-0.135715 -1.36608 6.43133 -2.85086 -0.61211 2.3204</acceleration>
          <wrench>-45.2418 -455.395 2143.94 0 -0 0</wrench>
        </link>
        <link name='back_right_wheel'>
          <pose frame=''>-2.91828 -0.396181 0.400002 4e-06 -0.015372 -0.023837</pose>
          <velocity>-0.000725 0.000273 0.000146 -0.000687 -0.002521 -0.00071</velocity>
          <acceleration>-1.22259 -0.90468 0.165885 -0.791553 0.34075 2.35272</acceleration>
          <wrench>-407.563 -301.584 55.2993 0 -0 0</wrench>
        </link>
        <link name='base_arm'>
          <pose frame=''>-3.65733 0.097154 1.2773 -2e-06 0.114339 -0.023839</pose>
          <velocity>0.001005 -0.000215 0.002647 0.001499 0.001628 -0.000635</velocity>
          <acceleration>4.37514 -5.06721 6.28538 -1.73151 -1.07585 -0.696969</acceleration>
          <wrench>1750.06 -2026.88 2514.15 0 -0 0</wrench>
        </link>
        <link name='body'>
          <pose frame=''>-1.6803 0.050017 0.225003 -1e-06 -2e-06 -0.023837</pose>
          <velocity>-0.000684 -6.9e-05 -0.000744 0.001536 0.001662 -0.000733</velocity>
          <acceleration>-0.57146 -1.19555 0.545992 -1.96065 -1.56016 -0.79919</acceleration>
          <wrench>-1428.65 -2988.88 1364.98 0 -0 0</wrench>
        </link>
        <link name='brackets'>
          <pose frame=''>-1.04666 0.034907 0.58636 -2e-06 0.091963 -0.023838</pose>
          <velocity>-8.3e-05 -0.00094 -0.001237 0.001558 0.001501 -0.000658</velocity>
          <acceleration>1.78398 -4.40762 -4.69774 1.31741 -1.23843 2.48015</acceleration>
          <wrench>22.9366 -56.6687 -60.3989 0 -0 0</wrench>
        </link>
        <link name='front_left_wheel'>
          <pose frame=''>-1.89611 0.530878 0.400001 2e-06 0.028125 -0.023837</pose>
          <velocity>1.1e-05 -0.000363 0.000175 0.00093 3.1e-05 -0.000625</velocity>
          <acceleration>-0.120761 -1.6574 0.648855 -2.11082 -0.658411 -0.648805</acceleration>
          <wrench>-40.2568 -552.507 216.301 0 -0 0</wrench>
        </link>
        <link name='front_right_wheel'>
          <pose frame=''>-1.91879 -0.420012 0.400003 1e-06 0.23746 -0.023837</pose>
          <velocity>-0.00074 -0.000213 -0.001084 0.001016 0.001634 -0.000754</velocity>
          <acceleration>-1.23495 -1.43261 -4.69133 -1.86539 0.83058 -0.794535</acceleration>
          <wrench>-411.679 -477.573 -1563.89 0 -0 0</wrench>
        </link>
        <link name='loader'>
          <pose frame=''>-1.38012 0.042855 0.088635 -2e-06 -0.009629 -0.023838</pose>
          <velocity>-0.000605 5.3e-05 -0.000914 0.001215 0.001115 -0.000899</velocity>
          <acceleration>-0.788259 -1.04369 -4.25856 1.25096 -0.336246 1.47453</acceleration>
          <wrench>-77.273 -102.313 -417.467 0 -0 0</wrench>
        </link>
        <link name='main_arm'>
          <pose frame=''>-3.3758 0.090443 1.77462 -2e-06 0.06298 -0.023838</pose>
          <velocity>0.001759 -0.001145 0.002162 0.001466 0.001456 -0.000674</velocity>
          <acceleration>2.60179 -4.15431 0.77177 1.25995 -0.791409 2.23206</acceleration>
          <wrench>780.536 -1246.29 231.531 0 -0 0</wrench>
        </link>
        <link name='supporter'>
          <pose frame=''>-3.03529 0.082324 0.8565 -2e-06 -0.16982 -0.023838</pose>
          <velocity>0.000393 -7.6e-05 0.001678 0.001511 0.001788 -0.000639</velocity>
          <acceleration>1.78745 -3.02792 1.36187 -1.84233 -0.870875 -0.525581</acceleration>
          <wrench>53.6236 -90.8376 40.856 0 -0 0</wrench>
        </link>
      </model>
      <model name='ground_plane'>
        <pose frame=''>0 0 0 0 -0 0</pose>
        <scale>1 1 1</scale>
        <link name='link'>
          <pose frame=''>0 0 0 0 -0 0</pose>
          <velocity>0 0 0 0 -0 0</velocity>
          <acceleration>0 0 0 0 -0 0</acceleration>
          <wrench>0 0 0 0 -0 0</wrench>
        </link>
      </model>
      <model name='sand_pile3'>
        <pose frame=''>-0.972054 -4.51104 0 0 -0 0</pose>
        <scale>1 1 1</scale>
        <link name='link_0'>
          <pose frame=''>-2.55364 -7.90992 0 0 -0 0</pose>
          <velocity>0 0 0 0 -0 0</velocity>
          <acceleration>0 0 0 0 -0 0</acceleration>
          <wrench>0 0 0 0 -0 0</wrench>
        </link>
      </model>
      <model name='sandy_plane'>
        <pose frame=''>-1.07592 1.8091 0 0 -0 0</pose>
        <scale>1 1 1</scale>
        <link name='link_8'>
          <pose frame=''>-1.07592 1.8091 0 0 -0 0</pose>
          <velocity>0 0 0 0 -0 0</velocity>
          <acceleration>0 0 0 0 -0 0</acceleration>
          <wrench>0 0 0 0 -0 0</wrench>
        </link>
      </model>
      <light name='sun'>
        <pose frame=''>0 0 10 0 -0 0</pose>
      </light>
    </state>
    <gui fullscreen='0'>
      <camera name='user_camera'>
        <pose frame=''>0.255021 -5.37468 2.4977 0 0.363643 1.7322</pose>
        <view_controller>orbit</view_controller>
        <projection_type>perspective</projection_type>
      </camera>
    </gui>
  </world>
</sdf>
